<?xml version="1.0" encoding="UTF-8"?>
<testsuite errors="1" failures="0" file="unittest/loader.py" name="unittest.loader._FailedTest-20200304115850" skipped="0" tests="1" time="0.021" timestamp="2020-03-04T11:58:50">
	<testcase classname="unittest.loader._FailedTest" file="/usr/lib/python3.6/unittest/loader.py" line="33" name="example_hello_tests" time="0.021" timestamp="2020-03-04T11:58:50">
		<error message="Failed to import test module: example_hello_tests
Traceback (most recent call last):
  File &quot;/usr/lib/python3.6/unittest/loader.py&quot;, line 153, in loadTestsFromName
    module = __import__(module_name)
  File &quot;/home/michael/workspace/python_pybuilder/src/unittest/python/example_hello_tests.py&quot;, line 1, in &lt;module&gt;
    from mockito import mock, verify
ModuleNotFoundError: No module named 'mockito'
" type="ImportError">
<![CDATA[ImportError: Failed to import test module: example_hello_tests
Traceback (most recent call last):
  File "/usr/lib/python3.6/unittest/loader.py", line 153, in loadTestsFromName
    module = __import__(module_name)
  File "/home/michael/workspace/python_pybuilder/src/unittest/python/example_hello_tests.py", line 1, in <module>
    from mockito import mock, verify
ModuleNotFoundError: No module named 'mockito'

]]>		</error>
		<system-out>
<![CDATA[]]>		</system-out>
		<system-err>
<![CDATA[]]>		</system-err>
	</testcase>
</testsuite>
